Workbook

Sheet Dashboard
A1: VUSLAT RECRUITMENT COMPANY | EXECUTIVE DASHBOARD
A2: Every figure below is a live formula. Add or edit rows on the operational sheets and this page updates itself - press F9 if Excel is in manual calculation mode. The records currently loaded are sample data - see section 4 of the Settings sheet before going live.
B3: =" Reporting currency: TJS (Somoni) | Report generated: "&TEXT(TODAY(),"DD MMMM YYYY")&" | Customers in pipeline: "&COUNTA(Customers!$A$4:$A$1003)&" | Active campaigns: "&COUNTIF('Marketing & Advertising'!$R$4:$R$1003,"Active") -> Reporting currency: TJS (Somoni) | Report generated: 30 July 2026 | Customers in pipeline: 12 | Active campaigns: 3
B5: OPERATIONAL KEY PERFORMANCE INDICATORS
B7: TOTAL LEADS | E7: CUSTOMERS CONTACTED | H7: CONSULTATION APPOINTMENTS | K7: CONSULTATIONS COMPLETED | N7: CONTRACTS SIGNED | Q7: ACTIVE CUSTOMERS
B8: =COUNTA('Lead Management'!$A$4:$A$1003) -> 30 | E8: =COUNT('Lead Management'!$S$4:$S$1003) -> 26 | H8: =COUNTA(Consultation!$A$4:$A$1003) -> 18 | K8: =COUNTIF(Consultation!$J$4:$J$1003,"Completed") -> 14 | N8: =COUNTA(Contracts!$A$4:$A$1003) -> 12 | Q8: =COUNTIF(Customers!$R$4:$R$1003,"Active") -> 9
B11: VISA APPLICATIONS SUBMITTED | E11: APPROVED VISAS | H11: REJECTED VISAS | K11: WORKERS SENT TO EUROPE | N11: PENDING CASES | Q11: COMPLETED CASES
B12: =COUNTIF('Process Tracking'!$AL$5:$AL$1003,"Completed") -> 8 | E12: =COUNTIF('Process Tracking'!$AT$5:$AT$1003,"Completed") -> 5 | H12: =COUNTIF('Process Tracking'!$AX$5:$AX$1003,"Completed") -> 1 | K12: =COUNTIF('Process Tracking'!$BF$5:$BF$1003,"Completed") -> 3 | N12: =COUNTA(Customers!$A$4:$A$1003)-COUNTIF(Customers!$R$4:$R$1003,"Completed")-COUNTIF(Customers!$R$4:$R$1003,"Cancelled") -> 9 | Q12: =COUNTIF('Process Tracking'!$BJ$5:$BJ$1003,"Completed") -> 2
B15: FINANCIAL KEY PERFORMANCE INDICATORS (all amounts in TJS)
B17: TODAY'S REVENUE | E17: MONTHLY REVENUE | H17: TOTAL PAYMENTS COLLECTED | K17: CONSULTATION FEES | N17: TOTAL REVENUE | Q17: OUTSTANDING PAYMENTS
B18: =SUMIFS(Finance!$E$4:$E$1003,Finance!$F$4:$F$1003,TODAY(),Finance!$J$4:$J$1003,"Paid") -> 9300 | E18: =SUMIFS(Finance!$E$4:$E$1003,Finance!$F$4:$F$1003,">="&EOMONTH(TODAY(),-1)+1,Finance!$F$4:$F$1003,"<="&EOMONTH(TODAY(),0),Finance!$J$4:$J$1003,"Paid") -> 9300 | H18: =Finance!$AA$4 -> 225250 | K18: =Finance!$AA$5 -> 700 | N18: =Finance!$AA$6 -> 225950 | Q18: =Finance!$AA$9 -> 12250
B21: ACCOUNTS RECEIVABLE | E21: TOTAL CONTRACT VALUE | H21: COMPANY EXPENSES | K21: NET PROFIT | N21: PROFIT MARGIN | Q21: COLLECTION RATE
B22: =Finance!$AA$10 -> 63750 | E22: =Finance!$AA$11 -> 289000 | H22: =Finance!$AA$18 -> 192300 | K22: =Finance!$AA$20 -> 33650 | N22: =Finance!$AA$21 -> 0.14892675 | Q22: =Finance!$AA$22 -> 0.77941176
B25: PERFORMANCE CHARTS

Sheet Lead Management
A1: VUSLAT RECRUITMENT COMPANY | LEAD MANAGEMENT
A2: One row per potential customer. Grey columns (I, U, V, W) are calculated - do not type in them. Use the drop-downs in columns G, K, L, M, N, O, Q, R.
A3: Lead ID | B3: Full Name | C3: Phone Number | D3: WhatsApp | E3: Email | F3: Passport Number | G3: Nationality | H3: Date of Birth | I3: Age | J3: Profession | K3: Education | L3: Russian Language Level | M3: English Language Level | N3: Preferred European Country | O3: Lead Source | P3: Registration Date | Q3: Assigned Sales Manager | R3: Lead Status | S3: Last Contact Date | T3: Next Follow-up Date | U3: Days Since Registration | V3: Consultation Booked | W3: Converted to Customer | X3: Notes
A4: LD-001 | B4: Firdavs Rahmonov | C4: +992 91 203 1137 | D4: +992 91 203 1137 | E4: firdavs1@mail.tj | F4: A4101373 | G4: Tajik | H4: 33767 | I4: =IF($H4="","",DATEDIF($H4,TODAY(),"Y")) -> 34 | J4: Truck Driver (CE) | K4: Vocational | L4: Intermediate | M4: Basic | N4: Poland | O4: Instagram | P4: 46030 | Q4: Nilufar Karimova | R4: Consultation Completed | S4: 46032 | U4: =IF($P4="","",TODAY()-$P4) -> 203 | V4: =IF($A4="","",IF(COUNTIF(Consultation!$B$4:$B$1003,$A4)>0,"Yes","No")) -> Yes | W4: =IF($A4="","",IF(COUNTIF(Customers!$B$4:$B$1003,$A4)>0,"Yes","No")) -> Yes | X4: Certified welder, 6 years experience in Russia.
A5: LD-002 | B5: Nilufar Sharipova | C5: +992 92 206 1274 | D5: +992 92 206 1274 | E5: nilufar2@mail.tj | F5: A4102746 | G5: Tajik | H5: 36487 | I5: =IF($H5="","",DATEDIF($H5,TODAY(),"Y")) -> 26 | J5: Nurse | K5: Bachelor | L5: Advanced | M5: Intermediate | N5: Germany | O5: Instagram | P5: 46037 | Q5: Jamshed Sattorov | R5: Consultation Completed | S5: 46039 | U5: =IF($P5="","",TODAY()-$P5) -> 196 | V5: =IF($A5="","",IF(COUNTIF(Consultation!$B$4:$B$1003,$A5)>0,"Yes","No")) -> Yes | W5: =IF($A5="","",IF(COUNTIF(Customers!$B$4:$B$1003,$A5)>0,"Yes","No")) -> Yes
A6: LD-003 | B6: Jamshed Karimov | C6: +992 93 209 1411 | D6: +992 93 209 1411 | E6: jamshed3@mail.tj | F6: A4104119 | G6: Tajik | H6: 32240 | I6: =IF($H6="","",DATEDIF($H6,TODAY(),"Y")) -> 38 | J6: Seamstress | K6: Master | L6: Fluent | M6: Advanced | N6: Czech Republic | O6: Facebook | P6: 46058 | Q6: Dilnoza Aliyeva | R6: Consultation Completed | S6: 46060 | U6: =IF($P6="","",TODAY()-$P6) -> 175 | V6: =IF($A6="","",IF(COUNTIF(Consultation!$B$4:$B$1003,$A6)>0,"Yes","No")) -> Yes | W6: =IF($A6="","",IF(COUNTIF(Customers!$B$4:$B$1003,$A6)>0,"Yes","No")) -> Yes | X6: Has valid Schengen refusal history - checked, cleared.
A7: LD-004 | B7: Zarina Nazriyeva | C7: +992 94 212 1548 | D7: +992 94 212 1548 | E7: zarina4@mail.tj | F7: A4105492 | G7: Tajik | H7: 34960 | I7: =IF($H7="","",DATEDIF($H7,TODAY(),"Y")) -> 30 | J7: Forklift Operator | K7: Secondary | L7: Basic | M7: None | N7: Poland | O7: Instagram | P7: 46065 | Q7: Nilufar Karimova | R7: Consultation Completed | S7: 46067 | U7: =IF($P7="","",TODAY()-$P7) -> 168 | V7: =IF($A7="","",IF(COUNTIF(Consultation!$B$4:$B$1003,$A7)>0,"Yes","No")) -> Yes | W7: =IF($A7="","",IF(COUNTIF(Customers!$B$4:$B$1003,$A7)>0,"Yes","No")) -> Yes
A8: LD-005 | B8: Bakhtiyor Umarov | C8: +992 95 215 1685 | D8: +992 95 215 1685 | E8: bakhtiyor5@mail.tj | F8: A4106865 | G8: Tajik | H8: 37289 | I8: =IF($H8="","",DATEDIF($H8,TODAY(),"Y")) -> 24 | J8: Welder | K8: Vocational | L8: Intermediate | M8: Basic | N8: Slovakia | O8: Website | P8: 46044 | Q8: Jamshed Sattorov | R8: Consultation Completed | S8: 46046 | U8: =IF($P8="","",TODAY()-$P8) -> 189 | V8: =IF($A8="","",IF(COUNTIF(Consultation!$B$4:$B$1003,$A8)>0,"Yes","No")) -> Yes | W8: =IF($A8="","",IF(COUNTIF(Customers!$B$4:$B$1003,$A8)>0,"Yes","No")) -> Yes | X8: Driving licence category CE, ready to travel immediately.
A9: LD-006 | B9: Manizha Qodirova | C9: +992 96 218 1822 | D9: +992 96 218 1822 | E9: manizha6@mail.tj | F9: A4108238 | G9: Tajik | H9: 33432 | I9: =IF($H9="","",DATEDIF($H9,TODAY(),"Y")) -> 35 | J9: Truck Driver (CE) | K9: Bachelor | L9: Advanced | M9: Intermediate | N9: Germany | O9: Referral | P9: 46071 | Q9: Dilnoza Aliyeva | R9: Consultation Completed | S9: 46073 | U9: =IF($P9="","",TODAY()-$P9) -> 162 | V9: =IF($A9="","",IF(COUNTIF(Consultation!$B$4:$B$1003,$A9)>0,"Yes","No")) -> Yes | W9: =IF($A9="","",IF(COUNTIF(Customers!$B$4:$B$1003,$A9)>0,"Yes","No")) -> Yes
A10: LD-007 | B10: Rustam Sattorov | C10: +992 97 221 1959 | D10: +992 97 221 1959 | E10: rustam7@mail.tj | F10: A4109611 | G10: Tajik | H10: 36153 | I10: =IF($H10="","",DATEDIF($H10,TODAY(),"Y")) -> 27 | J10: Nurse | K10: Master | L10: Fluent | M10: Advanced | N10: Poland | O10: Instagram | P10: 46085 | Q10: Nilufar Karimova | R10: Consultation Completed | S10: 46087 | U10: =IF($P10="","",TODAY()-$P10) -> 148 | V10: =IF($A10="","",IF(COUNTIF(Consultation!$B$4:$B$1003,$A10)>0,"Yes","No")) -> Yes | W10: =IF($A10="","",IF(COUNTIF(Customers!$B$4:$B$1003,$A10)>0,"Yes","No")) -> Yes
A11: LD-008 | B11: Dilnoza Aliyeva | C11: +992 90 224 2096 | D11: +992 90 224 2096 | E11: dilnoza8@mail.tj | F11: A4110984 | G11: Tajik | H11: 31905 | I11: =IF($H11="","",DATEDIF($H11,TODAY(),"Y")) -> 39 | J11: Seamstress | K11: Secondary | L11: Basic | M11: None | N11: Lithuania | O11: Instagram | P11: 46092 | Q11: Jamshed Sattorov | R11: Consultation Completed | S11: 46094 | U11: =IF($P11="","",TODAY()-$P11) -> 141 | V11: =IF($A11="","",IF(COUNTIF(Consultation!$B$4:$B$1003,$A11)>0,"Yes","No")) -> Yes | W11: =IF($A11="","",IF(COUNTIF(Customers!$B$4:$B$1003,$A11)>0,"Yes","No")) -> Yes | X11: Wants family reunification later, informed about the procedure.
A12: LD-009 | B12: Sherali Yusupov | C12: +992 91 227 2233 | D12: +992 91 227 2233 | E12: sherali9@mail.tj | F12: A4112357 | G12: Uzbek | H12: 34626 | I12: =IF($H12="","",DATEDIF($H12,TODAY(),"Y")) -> 31 | J12: Forklift Operator | K12: Vocational | L12: Intermediate | M12: Basic | N12: Czech Republic | O12: Facebook | P12: 46099 | Q12: Dilnoza Aliyeva | R12: Consultation Completed | S12: 46101 | U12: =IF($P12="","",TODAY()-$P12) -> 134 | V12: =IF($A12="","",IF(COUNTIF(Consultation!$B$4:$B$1003,$A12)>0,"Yes","No")) -> Yes | W12: =IF($A12="","",IF(COUNTIF(Customers!$B$4:$B$1003,$A12)>0,"Yes","No")) -> Yes
A13: LD-010 | B13: Malika Ismoilova | C13: +992 92 230 2370 | D13: +992 92 230 2370 | E13: malika10@mail.tj | F13: A4113730 | G13: Tajik | H13: 36953 | I13: =IF($H13="","",DATEDIF($H13,TODAY(),"Y")) -> 25 | J13: Welder | K13: Bachelor | L13: Advanced | M13: Intermediate | N13: Poland | O13: Instagram | P13: 46114 | Q13: Nilufar Karimova | R13: Consultation Completed | S13: 46116 | U13: =IF($P13="","",TODAY()-$P13) -> 119 | V13: =IF($A13="","",IF(COUNTIF(Consultation!$B$4:$B$1003,$A13)>0,"Yes","No")) -> Yes | W13: =IF($A13="","",IF(COUNTIF(Customers!$B$4:$B$1003,$A13)>0,"Yes","No")) -> Yes
A14: LD-011 | B14: Farrukh Davlatov | C14: +992 93 233 2507 | D14: +992 93 233 2507 | E14: farrukh11@mail.tj | F14: A4115103 | G14: Tajik | H14: 33099 | I14: =IF($H14="","",DATEDIF($H14,TODAY(),"Y")) -> 35 | J14: Truck Driver (CE) | K14: Master | L14: Fluent | M14: Advanced | N14: Hungary | O14: Website | P14: 46106 | Q14: Jamshed Sattorov | R14: Consultation Completed | S14: 46108 | U14: =IF($P14="","",TODAY()-$P14) -> 127 | V14: =IF($A14="","",IF(COUNTIF(Consultation!$B$4:$B$1003,$A14)>0,"Yes","No")) -> Yes | W14: =IF($A14="","",IF(COUNTIF(Customers!$B$4:$B$1003,$A14)>0,"Yes","No")) -> Yes
A15: LD-012 | B15: Gulnora Safarova | C15: +992 94 236 2644 | D15: +992 94 236 2644 | E15: gulnora12@mail.tj | F15: A4116476 | G15: Tajik | H15: 35455 | I15: =IF($H15="","",DATEDIF($H15,TODAY(),"Y")) -> 29 | J15: Nurse | K15: Secondary | L15: Basic | M15: None | N15: Romania | O15: Referral | P15: 46121 | Q15: Dilnoza Aliyeva | R15: Consultation Completed | S15: 46123 | U15: =IF($P15="","",TODAY()-$P15) -> 112 | V15: =IF($A15="","",IF(COUNTIF(Consultation!$B$4:$B$1003,$A15)>0,"Yes","No")) -> Yes | W15: =IF($A15="","",IF(COUNTIF(Customers!$B$4:$B$1003,$A15)>0,"Yes","No")) -> Yes | X15: Referred by CUS-006. Speaks basic Polish.
A16: LD-013 | B16: Umed Nazriev | C16: +992 95 239 2781 | D16: +992 95 239 2781 | E16: umed13@mail.tj | F16: A4117849 | G16: Tajik | H16: 31572 | I16: =IF($H16="","",DATEDIF($H16,TODAY(),"Y")) -> 40 | J16: Seamstress | K16: Vocational | L16: Intermediate | M16: Basic | N16: Germany | O16: Instagram | P16: 46128 | Q16: Nilufar Karimova | R16: Consultation Completed | S16: 46130 | U16: =IF($P16="","",TODAY()-$P16) -> 105 | V16: =IF($A16="","",IF(COUNTIF(Consultation!$B$4:$B$1003,$A16)>0,"Yes","No")) -> Yes | W16: =IF($A16="","",IF(COUNTIF(Customers!$B$4:$B$1003,$A16)>0,"Yes","No")) -> No
A17: LD-014 | B17: Shahnoza Rajabova | C17: +992 96 242 2918 | D17: +992 96 242 2918 | E17: shahnoza14@mail.tj | F17: A4119222 | G17: Tajik | H17: 34293 | I17: =IF($H17="","",DATEDIF($H17,TODAY(),"Y")) -> 32 | J17: Forklift Operator | K17: Bachelor | L17: Advanced | M17: Intermediate | N17: Poland | O17: Facebook | P17: 46115 | Q17: Jamshed Sattorov | R17: Consultation Completed | S17: 46117 | U17: =IF($P17="","",TODAY()-$P17) -> 118 | V17: =IF($A17="","",IF(COUNTIF(Consultation!$B$4:$B$1003,$A17)>0,"Yes","No")) -> Yes | W17: =IF($A17="","",IF(COUNTIF(Customers!$B$4:$B$1003,$A17)>0,"Yes","No")) -> No
A18: LD-015 | B18: Iskandar Mirzoev | C18: +992 97 245 3055 | D18: +992 97 245 3055 | E18: iskandar15@mail.tj | F18: A4120595 | G18: Tajik | H18: 36620 | I18: =IF($H18="","",DATEDIF($H18,TODAY(),"Y")) -> 26 | J18: Welder | K18: Master | L18: Fluent | M18: Advanced | N18: Poland | O18: Instagram | P18: 46149 | Q18: Dilnoza Aliyeva | R18: Consultation Scheduled | S18: 46151 | U18: =IF($P18="","",TODAY()-$P18) -> 84 | V18: =IF($A18="","",IF(COUNTIF(Consultation!$B$4:$B$1003,$A18)>0,"Yes","No")) -> Yes | W18: =IF($A18="","",IF(COUNTIF(Customers!$B$4:$B$1003,$A18)>0,"Yes","No")) -> No
A19: LD-016 | B19: Sitora Hakimova | C19: +992 90 248 3192 | D19: +992 90 248 3192 | E19: sitora16@mail.tj | F19: A4121968 | G19: Tajik | H19: 32766 | I19: =IF($H19="","",DATEDIF($H19,TODAY(),"Y")) -> 36 | J19: Truck Driver (CE) | K19: Secondary | L19: Basic | M19: None | N19: Czech Republic | O19: Instagram | P19: 46156 | Q19: Nilufar Karimova | R19: Consultation Scheduled | S19: 46158 | U19: =IF($P19="","",TODAY()-$P19) -> 77 | V19: =IF($A19="","",IF(COUNTIF(Consultation!$B$4:$B$1003,$A19)>0,"Yes","No")) -> Yes | W19: =IF($A19="","",IF(COUNTIF(Customers!$B$4:$B$1003,$A19)>0,"Yes","No")) -> No
A20: LD-017 | B20: Daler Ashurov | C20: +992 91 251 3329 | D20: +992 91 251 3329 | E20: daler17@mail.tj | F20: A4123341 | G20: Tajik | H20: 35121 | I20: =IF($H20="","",DATEDIF($H20,TODAY(),"Y")) -> 30 | J20: Nurse | K20: Vocational | L20: Intermediate | M20: Basic | N20: Slovakia | O20: Walk-in | P20: 46162 | Q20: Jamshed Sattorov | R20: Follow-up Required | S20: 46164 | T20: 46243 | U20: =IF($P20="","",TODAY()-$P20) -> 71 | V20: =IF($A20="","",IF(COUNTIF(Consultation!$B$4:$B$1003,$A20)>0,"Yes","No")) -> Yes | W20: =IF($A20="","",IF(COUNTIF(Customers!$B$4:$B$1003,$A20)>0,"Yes","No")) -> No | X20: Did not attend the consultation appointment - reschedule.
A21: LD-018 | B21: Nasiba Kholova | C21: +992 92 254 3466 | D21: +992 92 254 3466 | E21: nasiba18@mail.tj | F21: A4124714 | G21: Uzbek | H21: 31238 | I21: =IF($H21="","",DATEDIF($H21,TODAY(),"Y")) -> 41 | J21: Seamstress | K21: Bachelor | L21: Advanced | M21: Intermediate | N21: Germany | O21: Website | P21: 46170 | Q21: Dilnoza Aliyeva | R21: Not Interested | S21: 46172 | U21: =IF($P21="","",TODAY()-$P21) -> 63 | V21: =IF($A21="","",IF(COUNTIF(Consultation!$B$4:$B$1003,$A21)>0,"Yes","No")) -> Yes | W21: =IF($A21="","",IF(COUNTIF(Customers!$B$4:$B$1003,$A21)>0,"Yes","No")) -> No | X21: Decided to travel to Russia instead. Archived.
A22: LD-019 | B22: Parviz Odinaev | C22: +992 93 257 3603 | D22: +992 93 257 3603 | E22: parviz19@mail.tj | F22: A4126087 | G22: Tajik | H22: 33959 | I22: =IF($H22="","",DATEDIF($H22,TODAY(),"Y")) -> 33 | J22: Forklift Operator | K22: Master | L22: Fluent | M22: Advanced | N22: Poland | O22: Instagram | P22: 46176 | Q22: Nilufar Karimova | R22: New Lead | U22: =IF($P22="","",TODAY()-$P22) -> 57 | V22: =IF($A22="","",IF(COUNTIF(Consultation!$B$4:$B$1003,$A22)>0,"Yes","No")) -> No | W22: =IF($A22="","",IF(COUNTIF(Customers!$B$4:$B$1003,$A22)>0,"Yes","No")) -> No
A23: LD-020 | B23: Mavluda Ergasheva | C23: +992 94 260 3740 | D23: +992 94 260 3740 | E23: mavluda20@mail.tj | F23: A4127460 | G23: Tajik | H23: 36285 | I23: =IF($H23="","",DATEDIF($H23,TODAY(),"Y")) -> 27 | J23: Welder | K23: Secondary | L23: Basic | M23: None | N23: Lithuania | O23: Instagram | P23: 46183 | Q23: Jamshed Sattorov | R23: Contacted | S23: 46185 | T23: 46236 | U23: =IF($P23="","",TODAY()-$P23) -> 50 | V23: =IF($A23="","",IF(COUNTIF(Consultation!$B$4:$B$1003,$A23)>0,"Yes","No")) -> No | W23: =IF($A23="","",IF(COUNTIF(Customers!$B$4:$B$1003,$A23)>0,"Yes","No")) -> No
A24: LD-021 | B24: Sorbon Latifov | C24: +992 95 263 3877 | D24: +992 95 263 3877 | E24: sorbon21@mail.tj | F24: A4128833 | G24: Tajik | H24: 32432 | I24: =IF($H24="","",DATEDIF($H24,TODAY(),"Y")) -> 37 | J24: Truck Driver (CE) | K24: Vocational | L24: Intermediate | M24: Basic | N24: Germany | O24: Facebook | P24: 46188 | Q24: Dilnoza Aliyeva | R24: Contacted | S24: 46190 | T24: 46237 | U24: =IF($P24="","",TODAY()-$P24) -> 45 | V24: =IF($A24="","",IF(COUNTIF(Consultation!$B$4:$B$1003,$A24)>0,"Yes","No")) -> No | W24: =IF($A24="","",IF(COUNTIF(Customers!$B$4:$B$1003,$A24)>0,"Yes","No")) -> No
A25: LD-022 | B25: Zulfiya Muminova | C25: +992 96 266 4014 | D25: +992 96 266 4014 | E25: zulfiya22@mail.tj | F25: A4130206 | G25: Tajik | H25: 34785 | I25: =IF($H25="","",DATEDIF($H25,TODAY(),"Y")) -> 31 | J25: Nurse | K25: Bachelor | L25: Advanced | M25: Intermediate | N25: Poland | O25: Referral | P25: 46193 | Q25: Nilufar Karimova | R25: No Answer | S25: 46195 | T25: 46238 | U25: =IF($P25="","",TODAY()-$P25) -> 40 | V25: =IF($A25="","",IF(COUNTIF(Consultation!$B$4:$B$1003,$A25)>0,"Yes","No")) -> No | W25: =IF($A25="","",IF(COUNTIF(Customers!$B$4:$B$1003,$A25)>0,"Yes","No")) -> No | X25: Requested a call back after Ramadan.
A26: LD-023 | B26: Amirbek Turaev | C26: +992 97 269 4151 | D26: +992 97 269 4151 | E26: amirbek23@mail.tj | F26: A4131579 | G26: Tajik | H26: 37479 | I26: =IF($H26="","",DATEDIF($H26,TODAY(),"Y")) -> 23 | J26: Seamstress | K26: Master | L26: Fluent | M26: Advanced | N26: Czech Republic | O26: Instagram | P26: 46198 | Q26: Jamshed Sattorov | R26: Follow-up Required | S26: 46200 | T26: 46239 | U26: =IF($P26="","",TODAY()-$P26) -> 35 | V26: =IF($A26="","",IF(COUNTIF(Consultation!$B$4:$B$1003,$A26)>0,"Yes","No")) -> No | W26: =IF($A26="","",IF(COUNTIF(Customers!$B$4:$B$1003,$A26)>0,"Yes","No")) -> No
A27: LD-024 | B27: Nigina Saidova | C27: +992 90 272 4288 | D27: +992 90 272 4288 | E27: nigina24@mail.tj | F27: A4132952 | G27: Tajik | H27: 33260 | I27: =IF($H27="","",DATEDIF($H27,TODAY(),"Y")) -> 35 | J27: Forklift Operator | K27: Secondary | L27: Basic | M27: None | N27: Netherlands | O27: Website | P27: 46204 | Q27: Dilnoza Aliyeva | R27: New Lead | U27: =IF($P27="","",TODAY()-$P27) -> 29 | V27: =IF($A27="","",IF(COUNTIF(Consultation!$B$4:$B$1003,$A27)>0,"Yes","No")) -> No | W27: =IF($A27="","",IF(COUNTIF(Customers!$B$4:$B$1003,$A27)>0,"Yes","No")) -> No
A28: LD-025 | B28: Behruz Rahimov | C28: +992 91 275 4425 | D28: +992 91 275 4425 | E28: behruz25@mail.tj | F28: A4134325 | G28: Tajik | H28: 35952 | I28: =IF($H28="","",DATEDIF($H28,TODAY(),"Y")) -> 28 | J28: Welder | K28: Vocational | L28: Intermediate | M28: Basic | N28: Poland | O28: Instagram | P28: 46209 | Q28: Nilufar Karimova | R28: Contacted | S28: 46211 | T28: 46241 | U28: =IF($P28="","",TODAY()-$P28) -> 24 | V28: =IF($A28="","",IF(COUNTIF(Consultation!$B$4:$B$1003,$A28)>0,"Yes","No")) -> No | W28: =IF($A28="","",IF(COUNTIF(Customers!$B$4:$B$1003,$A28)>0,"Yes","No")) -> No
A29: LD-026 | B29: Mehrangez Boboeva | C29: +992 92 278 4562 | D29: +992 92 278 4562 | E29: mehrangez26@mail.tj | F29: A4135698 | G29: Tajik | H29: 32098 | I29: =IF($H29="","",DATEDIF($H29,TODAY(),"Y")) -> 38 | J29: Truck Driver (CE) | K29: Bachelor | L29: Advanced | M29: Intermediate | N29: Portugal | O29: Walk-in | P29: 46213 | Q29: Jamshed Sattorov | R29: On Hold | S29: 46215 | T29: 46242 | U29: =IF($P29="","",TODAY()-$P29) -> 20 | V29: =IF($A29="","",IF(COUNTIF(Consultation!$B$4:$B$1003,$A29)>0,"Yes","No")) -> No | W29: =IF($A29="","",IF(COUNTIF(Customers!$B$4:$B$1003,$A29)>0,"Yes","No")) -> No | X29: Walk-in from the Dushanbe office, brochure handed out.
A30: LD-027 | B30: Sanjar Ochilov | C30: +992 93 281 4699 | D30: +992 93 281 4699 | E30: sanjar27@mail.tj | F30: A4137071 | G30: Uzbek | H30: 34425 | I30: =IF($H30="","",DATEDIF($H30,TODAY(),"Y")) -> 32 | J30: Nurse | K30: Master | L30: Fluent | M30: Advanced | N30: Germany | O30: Instagram | P30: 46218 | Q30: Dilnoza Aliyeva | R30: New Lead | U30: =IF($P30="","",TODAY()-$P30) -> 15 | V30: =IF($A30="","",IF(COUNTIF(Consultation!$B$4:$B$1003,$A30)>0,"Yes","No")) -> No | W30: =IF($A30="","",IF(COUNTIF(Customers!$B$4:$B$1003,$A30)>0,"Yes","No")) -> No
A31: LD-028 | B31: Firuza Yatimova | C31: +992 94 284 4836 | D31: +992 94 284 4836 | E31: firuza28@mail.tj | F31: A4138444 | G31: Tajik | H31: 37146 | I31: =IF($H31="","",DATEDIF($H31,TODAY(),"Y")) -> 24 | J31: Seamstress | K31: Secondary | L31: Basic | M31: None | N31: Poland | O31: Referral | P31: 46221 | Q31: Nilufar Karimova | R31: No Answer | S31: 46223 | T31: 46244 | U31: =IF($P31="","",TODAY()-$P31) -> 12 | V31: =IF($A31="","",IF(COUNTIF(Consultation!$B$4:$B$1003,$A31)>0,"Yes","No")) -> No | W31: =IF($A31="","",IF(COUNTIF(Customers!$B$4:$B$1003,$A31)>0,"Yes","No")) -> No
A32: LD-029 | B32: Komron Salimov | C32: +992 95 287 4973 | D32: +992 95 287 4973 | E32: komron29@mail.tj | F32: A4139817 | G32: Tajik | H32: 32927 | I32: =IF($H32="","",DATEDIF($H32,TODAY(),"Y")) -> 36 | J32: Forklift Operator | K32: Vocational | L32: Intermediate | M32: Basic | N32: Croatia | O32: Instagram | P32: 46225 | Q32: Jamshed Sattorov | R32: Follow-up Required | S32: 46227 | T32: 46245 | U32: =IF($P32="","",TODAY()-$P32) -> 8 | V32: =IF($A32="","",IF(COUNTIF(Consultation!$B$4:$B$1003,$A32)>0,"Yes","No")) -> No | W32: =IF($A32="","",IF(COUNTIF(Customers!$B$4:$B$1003,$A32)>0,"Yes","No")) -> No
A33: LD-030 | B33: Anisa Juraeva | C33: +992 96 290 5110 | D33: +992 96 290 5110 | E33: anisa30@mail.tj | F33: A4141190 | G33: Tajik | H33: 35618 | I33: =IF($H33="","",DATEDIF($H33,TODAY(),"Y")) -> 29 | J33: Welder | K33: Bachelor | L33: Advanced | M33: Intermediate | N33: Poland | O33: Website | P33: 46230 | Q33: Dilnoza Aliyeva | R33: New Lead | U33: =IF($P33="","",TODAY()-$P33) -> 3 | V33: =IF($A33="","",IF(COUNTIF(Consultation!$B$4:$B$1003,$A33)>0,"Yes","No")) -> No | W33: =IF($A33="","",IF(COUNTIF(Customers!$B$4:$B$1003,$A33)>0,"Yes","No")) -> No
I34: =IF($H34="","",DATEDIF($H34,TODAY(),"Y")) | U34: =IF($P34="","",TODAY()-$P34) | V34: =IF($A34="","",IF(COUNTIF(Consultation!$B$4:$B$1003,$A34)>0,"Yes","No")) | W34: =IF($A34="","",IF(COUNTIF(Customers!$B$4:$B$1003,$A34)>0,"Yes","No"))
I35: =IF($H35="","",DATEDIF($H35,TODAY(),"Y")) | U35: =IF($P35="","",TODAY()-$P35) | V35: =IF($A35="","",IF(COUNTIF(Consultation!$B$4:$B$1003,$A35)>0,"Yes","No")) | W35: =IF($A35="","",IF(COUNTIF(Customers!$B$4:$B$1003,$A35)>0,"Yes","No"))
I36: =IF($H36="","",DATEDIF($H36,TODAY(),"Y")) | U36: =IF($P36="","",TODAY()-$P36) | V36: =IF($A36="","",IF(COUNTIF(Consultation!$B$4:$B$1003,$A36)>0,"Yes","No")) | W36: =IF($A36="","",IF(COUNTIF(Customers!$B$4:$B$1003,$A36)>0,"Yes","No"))
I37: =IF($H37="","",DATEDIF($H37,TODAY(),"Y")) | U37: =IF($P37="","",TODAY()-$P37) | V37: =IF($A37="","",IF(COUNTIF(Consultation!$B$4:$B$1003,$A37)>0,"Yes","No")) | W37: =IF($A37="","",IF(COUNTIF(Customers!$B$4:$B$1003,$A37)>0,"Yes","No"))
I38: =IF($H38="","",DATEDIF($H38,TODAY(),"Y")) | U38: =IF($P38="","",TODAY()-$P38) | V38: =IF($A38="","",IF(COUNTIF(Consultation!$B$4:$B$1003,$A38)>0,"Yes","No")) | W38: =IF($A38="","",IF(COUNTIF(Customers!$B$4:$B$1003,$A38)>0,"Yes","No"))
I39: =IF($H39="","",DATEDIF($H39,TODAY(),"Y")) | U39: =IF($P39="","",TODAY()-$P39) | V39: =IF($A39="","",IF(COUNTIF(Consultation!$B$4:$B$1003,$A39)>0,"Yes","No")) | W39: =IF($A39="","",IF(COUNTIF(Customers!$B$4:$B$1003,$A39)>0,"Yes","No"))
I40: =IF($H40="","",DATEDIF($H40,TODAY(),"Y")) | U40: =IF($P40="","",TODAY()-$P40) | V40: =IF($A40="","",IF(COUNTIF(Consultation!$B$4:$B$1003,$A40)>0,"Yes","No")) | W40: =IF($A40="","",IF(COUNTIF(Customers!$B$4:$B$1003,$A40)>0,"Yes","No"))
...

Sheet Consultation
A1: VUSLAT RECRUITMENT COMPANY | CONSULTATION
A2: Every candidate pays a 50 TJS in-office consultation fee. Type the Lead ID in column B - the name, phone and fee fill in automatically.
A3: Consultation ID | B3: Lead ID | C3: Full Name | D3: Phone | E3: Consultation Date | F3: Time | G3: Consultant | H3: Consultation Fee (TJS) | I3: Payment Status | J3: Consultation Status | K3: Customer Evaluation | L3: Recommended Country | M3: Recommended Job | N3: Next Action | O3: Consultant Notes | P3: Converted to Customer | Q3: Days Since Consultation
A4: CNS-001 | B4: LD-001 | C4: =IFERROR(INDEX('Lead Management'!$B$4:$B$1003,MATCH($B4,'Lead Management'!$A$4:$A$1003,0)),"") -> Firdavs Rahmonov | D4: =IFERROR(INDEX('Lead Management'!$C$4:$C$1003,MATCH($B4,'Lead Management'!$A$4:$A$1003,0)),"") -> +992 91 203 1137 | E4: 46035 | F4: 10:00 | G4: Zarina Nazarova | H4: =IF($A4="","",Settings!$B$8) -> 50 | I4: Paid | J4: Completed | K4: Strong Candidate | L4: Poland | M4: Welder | N4: Prepare Contract | P4: =IF($B4="","",IF(COUNTIF(Customers!$B$4:$B$1003,$B4)>0,"Yes","No")) -> Yes | Q4: =IF($E4="","",IF($E4>TODAY(),"Scheduled",TODAY()-$E4)) -> 198
A5: CNS-002 | B5: LD-002 | C5: =IFERROR(INDEX('Lead Management'!$B$4:$B$1003,MATCH($B5,'Lead Management'!$A$4:$A$1003,0)),"") -> Nilufar Sharipova | D5: =IFERROR(INDEX('Lead Management'!$C$4:$C$1003,MATCH($B5,'Lead Management'!$A$4:$A$1003,0)),"") -> +992 92 206 1274 | E5: 46042 | F5: 11:30 | G5: Dilnoza Aliyeva | H5: =IF($A5="","",Settings!$B$8) -> 50 | I5: Paid | J5: Completed | K5: Strong Candidate | L5: Germany | M5: Warehouse Operator | N5: Prepare Contract | P5: =IF($B5="","",IF(COUNTIF(Customers!$B$4:$B$1003,$B5)>0,"Yes","No")) -> Yes | Q5: =IF($E5="","",IF($E5>TODAY(),"Scheduled",TODAY()-$E5)) -> 191
A6: CNS-003 | B6: LD-003 | C6: =IFERROR(INDEX('Lead Management'!$B$4:$B$1003,MATCH($B6,'Lead Management'!$A$4:$A$1003,0)),"") -> Jamshed Karimov | D6: =IFERROR(INDEX('Lead Management'!$C$4:$C$1003,MATCH($B6,'Lead Management'!$A$4:$A$1003,0)),"") -> +992 93 209 1411 | E6: 46063 | F6: 12:00 | G6: Zarina Nazarova | H6: =IF($A6="","",Settings!$B$8) -> 50 | I6: Paid | J6: Completed | K6: Good Candidate | L6: Czech Republic | M6: Construction Worker | N6: Prepare Contract | P6: =IF($B6="","",IF(COUNTIF(Customers!$B$4:$B$1003,$B6)>0,"Yes","No")) -> Yes | Q6: =IF($E6="","",IF($E6>TODAY(),"Scheduled",TODAY()-$E6)) -> 170
A7: CNS-004 | B7: LD-004 | C7: =IFERROR(INDEX('Lead Management'!$B$4:$B$1003,MATCH($B7,'Lead Management'!$A$4:$A$1003,0)),"") -> Zarina Nazriyeva | D7: =IFERROR(INDEX('Lead Management'!$C$4:$C$1003,MATCH($B7,'Lead Management'!$A$4:$A$1003,0)),"") -> +992 94 212 1548 | E7: 46070 | F7: 13:30 | G7: Dilnoza Aliyeva | H7: =IF($A7="","",Settings!$B$8) -> 50 | I7: Paid | J7: Completed | K7: Strong Candidate | L7: Poland | M7: Electrician | N7: Prepare Contract | P7: =IF($B7="","",IF(COUNTIF(Customers!$B$4:$B$1003,$B7)>0,"Yes","No")) -> Yes | Q7: =IF($E7="","",IF($E7>TODAY(),"Scheduled",TODAY()-$E7)) -> 163
A8: CNS-005 | B8: LD-005 | C8: =IFERROR(INDEX('Lead Management'!$B$4:$B$1003,MATCH($B8,'Lead Management'!$A$4:$A$1003,0)),"") -> Bakhtiyor Umarov | D8: =IFERROR(INDEX('Lead Management'!$C$4:$C$1003,MATCH($B8,'Lead Management'!$A$4:$A$1003,0)),"") -> +992 95 215 1685 | E8: 46049 | F8: 14:00 | G8: Zarina Nazarova | H8: =IF($A8="","",Settings!$B$8) -> 50 | I8: Paid | J8: Completed | K8: Good Candidate | L8: Slovakia | M8: Truck Driver (CE) | N8: Prepare Contract | P8: =IF($B8="","",IF(COUNTIF(Customers!$B$4:$B$1003,$B8)>0,"Yes","No")) -> Yes | Q8: =IF($E8="","",IF($E8>TODAY(),"Scheduled",TODAY()-$E8)) -> 184
A9: CNS-006 | B9: LD-006 | C9: =IFERROR(INDEX('Lead Management'!$B$4:$B$1003,MATCH($B9,'Lead Management'!$A$4:$A$1003,0)),"") -> Manizha Qodirova | D9: =IFERROR(INDEX('Lead Management'!$C$4:$C$1003,MATCH($B9,'Lead Management'!$A$4:$A$1003,0)),"") -> +992 96 218 1822 | E9: 46076 | F9: 15:30 | G9: Dilnoza Aliyeva | H9: =IF($A9="","",Settings!$B$8) -> 50 | I9: Paid | J9: Completed | K9: Strong Candidate | L9: Germany | M9: Chef | N9: Prepare Contract | P9: =IF($B9="","",IF(COUNTIF(Customers!$B$4:$B$1003,$B9)>0,"Yes","No")) -> Yes | Q9: =IF($E9="","",IF($E9>TODAY(),"Scheduled",TODAY()-$E9)) -> 157
A10: CNS-007 | B10: LD-007 | C10: =IFERROR(INDEX('Lead Management'!$B$4:$B$1003,MATCH($B10,'Lead Management'!$A$4:$A$1003,0)),"") -> Rustam Sattorov | D10: =IFERROR(INDEX('Lead Management'!$C$4:$C$1003,MATCH($B10,'Lead Management'!$A$4:$A$1003,0)),"") -> +992 97 221 1959 | E10: 46090 | F10: 16:00 | G10: Zarina Nazarova | H10: =IF($A10="","",Settings!$B$8) -> 50 | I10: Paid | J10: Completed | K10: Good Candidate | L10: Poland | M10: Construction Worker | N10: Prepare Contract | P10: =IF($B10="","",IF(COUNTIF(Customers!$B$4:$B$1003,$B10)>0,"Yes","No")) -> Yes | Q10: =IF($E10="","",IF($E10>TODAY(),"Scheduled",TODAY()-$E10)) -> 143
A11: CNS-008 | B11: LD-008 | C11: =IFERROR(INDEX('Lead Management'!$B$4:$B$1003,MATCH($B11,'Lead Management'!$A$4:$A$1003,0)),"") -> Dilnoza Aliyeva | D11: =IFERROR(INDEX('Lead Management'!$C$4:$C$1003,MATCH($B11,'Lead Management'!$A$4:$A$1003,0)),"") -> +992 90 224 2096 | E11: 46097 | F11: 09:30 | G11: Dilnoza Aliyeva | H11: =IF($A11="","",Settings!$B$8) -> 50 | I11: Paid | J11: Completed | K11: Good Candidate | L11: Lithuania | M11: Warehouse Operator | N11: Prepare Contract | P11: =IF($B11="","",IF(COUNTIF(Customers!$B$4:$B$1003,$B11)>0,"Yes","No")) -> Yes | Q11: =IF($E11="","",IF($E11>TODAY(),"Scheduled",TODAY()-$E11)) -> 136
A12: CNS-009 | B12: LD-009 | C12: =IFERROR(INDEX('Lead Management'!$B$4:$B$1003,MATCH($B12,'Lead Management'!$A$4:$A$1003,0)),"") -> Sherali Yusupov | D12: =IFERROR(INDEX('Lead Management'!$C$4:$C$1003,MATCH($B12,'Lead Management'!$A$4:$A$1003,0)),"") -> +992 91 227 2233 | E12: 46104 | F12: 10:00 | G12: Zarina Nazarova | H12: =IF($A12="","",Settings!$B$8) -> 50 | I12: Paid | J12: Completed | K12: Average Candidate | L12: Czech Republic | M12: Plumber | N12: Prepare Contract | P12: =IF($B12="","",IF(COUNTIF(Customers!$B$4:$B$1003,$B12)>0,"Yes","No")) -> Yes | Q12: =IF($E12="","",IF($E12>TODAY(),"Scheduled",TODAY()-$E12)) -> 129
A13: CNS-010 | B13: LD-010 | C13: =IFERROR(INDEX('Lead Management'!$B$4:$B$1003,MATCH($B13,'Lead Management'!$A$4:$A$1003,0)),"") -> Malika Ismoilova | D13: =IFERROR(INDEX('Lead Management'!$C$4:$C$1003,MATCH($B13,'Lead Management'!$A$4:$A$1003,0)),"") -> +992 92 230 2370 | E13: 46119 | F13: 11:30 | G13: Dilnoza Aliyeva | H13: =IF($A13="","",Settings!$B$8) -> 50 | I13: Paid | J13: Completed | K13: Good Candidate | L13: Poland | M13: Painter | N13: Prepare Contract | P13: =IF($B13="","",IF(COUNTIF(Customers!$B$4:$B$1003,$B13)>0,"Yes","No")) -> Yes | Q13: =IF($E13="","",IF($E13>TODAY(),"Scheduled",TODAY()-$E13)) -> 114
A14: CNS-011 | B14: LD-011 | C14: =IFERROR(INDEX('Lead Management'!$B$4:$B$1003,MATCH($B14,'Lead Management'!$A$4:$A$1003,0)),"") -> Farrukh Davlatov | D14: =IFERROR(INDEX('Lead Management'!$C$4:$C$1003,MATCH($B14,'Lead Management'!$A$4:$A$1003,0)),"") -> +992 93 233 2507 | E14: 46111 | F14: 12:00 | G14: Zarina Nazarova | H14: =IF($A14="","",Settings!$B$8) -> 50 | I14: Paid | J14: Completed | K14: Average Candidate | L14: Hungary | M14: Agricultural Worker | N14: Prepare Contract | P14: =IF($B14="","",IF(COUNTIF(Customers!$B$4:$B$1003,$B14)>0,"Yes","No")) -> Yes | Q14: =IF($E14="","",IF($E14>TODAY(),"Scheduled",TODAY()-$E14)) -> 122
A15: CNS-012 | B15: LD-012 | C15: =IFERROR(INDEX('Lead Management'!$B$4:$B$1003,MATCH($B15,'Lead Management'!$A$4:$A$1003,0)),"") -> Gulnora Safarova | D15: =IFERROR(INDEX('Lead Management'!$C$4:$C$1003,MATCH($B15,'Lead Management'!$A$4:$A$1003,0)),"") -> +992 94 236 2644 | E15: 46126 | F15: 13:30 | G15: Dilnoza Aliyeva | H15: =IF($A15="","",Settings!$B$8) -> 50 | I15: Paid | J15: Completed | K15: Average Candidate | L15: Romania | M15: Cleaner | N15: Prepare Contract | P15: =IF($B15="","",IF(COUNTIF(Customers!$B$4:$B$1003,$B15)>0,"Yes","No")) -> Yes | Q15: =IF($E15="","",IF($E15>TODAY(),"Scheduled",TODAY()-$E15)) -> 107
A16: CNS-013 | B16: LD-013 | C16: =IFERROR(INDEX('Lead Management'!$B$4:$B$1003,MATCH($B16,'Lead Management'!$A$4:$A$1003,0)),"") -> Umed Nazriev | D16: =IFERROR(INDEX('Lead Management'!$C$4:$C$1003,MATCH($B16,'Lead Management'!$A$4:$A$1003,0)),"") -> +992 95 239 2781 | E16: 46133 | F16: 14:00 | G16: Zarina Nazarova | H16: =IF($A16="","",Settings!$B$8) -> 50 | I16: Paid | J16: Completed | K16: Weak Candidate | L16: Germany | M16: Auto Mechanic | N16: Close - Not Suitable | O16: Weak documents, diploma not apostilled. Advised to prepare first. | P16: =IF($B16="","",IF(COUNTIF(Customers!$B$4:$B$1003,$B16)>0,"Yes","No")) -> No | Q16: =IF($E16="","",IF($E16>TODAY(),"Scheduled",TODAY()-$E16)) -> 100
A17: CNS-014 | B17: LD-014 | C17: =IFERROR(INDEX('Lead Management'!$B$4:$B$1003,MATCH($B17,'Lead Management'!$A$4:$A$1003,0)),"") -> Shahnoza Rajabova | D17: =IFERROR(INDEX('Lead Management'!$C$4:$C$1003,MATCH($B17,'Lead Management'!$A$4:$A$1003,0)),"") -> +992 96 242 2918 | E17: 46120 | F17: 15:30 | G17: Dilnoza Aliyeva | H17: =IF($A17="","",Settings!$B$8) -> 50 | I17: Paid | J17: Completed | K17: Average Candidate | L17: Poland | M17: Forklift Operator | N17: Await Client Decision | O17: Good profile but wants to postpone the departure to next year. | P17: =IF($B17="","",IF(COUNTIF(Customers!$B$4:$B$1003,$B17)>0,"Yes","No")) -> No | Q17: =IF($E17="","",IF($E17>TODAY(),"Scheduled",TODAY()-$E17)) -> 113
A18: CNS-015 | B18: LD-015 | C18: =IFERROR(INDEX('Lead Management'!$B$4:$B$1003,MATCH($B18,'Lead Management'!$A$4:$A$1003,0)),"") -> Iskandar Mirzoev | D18: =IFERROR(INDEX('Lead Management'!$C$4:$C$1003,MATCH($B18,'Lead Management'!$A$4:$A$1003,0)),"") -> +992 97 245 3055 | E18: 46237 | F18: 16:00 | G18: Zarina Nazarova | H18: =IF($A18="","",Settings!$B$8) -> 50 | I18: Pending | J18: Scheduled | L18: Poland | M18: Welder | N18: Collect Documents | P18: =IF($B18="","",IF(COUNTIF(Customers!$B$4:$B$1003,$B18)>0,"Yes","No")) -> No | Q18: =IF($E18="","",IF($E18>TODAY(),"Scheduled",TODAY()-$E18)) -> Scheduled
A19: CNS-016 | B19: LD-016 | C19: =IFERROR(INDEX('Lead Management'!$B$4:$B$1003,MATCH($B19,'Lead Management'!$A$4:$A$1003,0)),"") -> Sitora Hakimova | D19: =IFERROR(INDEX('Lead Management'!$C$4:$C$1003,MATCH($B19,'Lead Management'!$A$4:$A$1003,0)),"") -> +992 90 248 3192 | E19: 46238 | F19: 09:30 | G19: Dilnoza Aliyeva | H19: =IF($A19="","",Settings!$B$8) -> 50 | I19: Pending | J19: Scheduled | L19: Czech Republic | M19: Warehouse Operator | N19: Collect Documents | P19: =IF($B19="","",IF(COUNTIF(Customers!$B$4:$B$1003,$B19)>0,"Yes","No")) -> No | Q19: =IF($E19="","",IF($E19>TODAY(),"Scheduled",TODAY()-$E19)) -> Scheduled
A20: CNS-017 | B20: LD-017 | C20: =IFERROR(INDEX('Lead Management'!$B$4:$B$1003,MATCH($B20,'Lead Management'!$A$4:$A$1003,0)),"") -> Daler Ashurov | D20: =IFERROR(INDEX('Lead Management'!$C$4:$C$1003,MATCH($B20,'Lead Management'!$A$4:$A$1003,0)),"") -> +992 91 251 3329 | E20: 46168 | F20: 10:00 | G20: Zarina Nazarova | H20: =IF($A20="","",Settings!$B$8) -> 50 | I20: Cancelled | J20: No-show | L20: Slovakia | M20: Construction Worker | N20: Schedule Follow-up | O20: Client did not come to the office. Fee not collected. | P20: =IF($B20="","",IF(COUNTIF(Customers!$B$4:$B$1003,$B20)>0,"Yes","No")) -> No | Q20: =IF($E20="","",IF($E20>TODAY(),"Scheduled",TODAY()-$E20)) -> 65
A21: CNS-018 | B21: LD-018 | C21: =IFERROR(INDEX('Lead Management'!$B$4:$B$1003,MATCH($B21,'Lead Management'!$A$4:$A$1003,0)),"") -> Nasiba Kholova | D21: =IFERROR(INDEX('Lead Management'!$C$4:$C$1003,MATCH($B21,'Lead Management'!$A$4:$A$1003,0)),"") -> +992 92 254 3466 | E21: 46176 | F21: 11:30 | G21: Dilnoza Aliyeva | H21: =IF($A21="","",Settings!$B$8) -> 50 | I21: Cancelled | J21: Cancelled | L21: Germany | M21: Seamstress | N21: Close - Not Suitable | O21: Client cancelled one day before the appointment. | P21: =IF($B21="","",IF(COUNTIF(Customers!$B$4:$B$1003,$B21)>0,"Yes","No")) -> No | Q21: =IF($E21="","",IF($E21>TODAY(),"Scheduled",TODAY()-$E21)) -> 57
C22: =IFERROR(INDEX('Lead Management'!$B$4:$B$1003,MATCH($B22,'Lead Management'!$A$4:$A$1003,0)),"") | D22: =IFERROR(INDEX('Lead Management'!$C$4:$C$1003,MATCH($B22,'Lead Management'!$A$4:$A$1003,0)),"") | H22: =IF($A22="","",Settings!$B$8) | P22: =IF($B22="","",IF(COUNTIF(Customers!$B$4:$B$1003,$B22)>0,"Yes","No")) | Q22: =IF($E22="","",IF($E22>TODAY(),"Scheduled",TODAY()-$E22))
C23: =IFERROR(INDEX('Lead Management'!$B$4:$B$1003,MATCH($B23,'Lead Management'!$A$4:$A$1003,0)),"") | D23: =IFERROR(INDEX('Lead Management'!$C$4:$C$1003,MATCH($B23,'Lead Management'!$A$4:$A$1003,0)),"") | H23: =IF($A23="","",Settings!$B$8) | P23: =IF($B23="","",IF(COUNTIF(Customers!$B$4:$B$1003,$B23)>0,"Yes","No")) | Q23: =IF($E23="","",IF($E23>TODAY(),"Scheduled",TODAY()-$E23))
C24: =IFERROR(INDEX('Lead Management'!$B$4:$B$1003,MATCH($B24,'Lead Management'!$A$4:$A$1003,0)),"") | D24: =IFERROR(INDEX('Lead Management'!$C$4:$C$1003,MATCH($B24,'Lead Management'!$A$4:$A$1003,0)),"") | H24: =IF($A24="","",Settings!$B$8) | P24: =IF($B24="","",IF(COUNTIF(Customers!$B$4:$B$1003,$B24)>0,"Yes","No")) | Q24: =IF($E24="","",IF($E24>TODAY(),"Scheduled",TODAY()-$E24))
C25: =IFERROR(INDEX('Lead Management'!$B$4:$B$1003,MATCH($B25,'Lead Management'!$A$4:$A$1003,0)),"") | D25: =IFERROR(INDEX('Lead Management'!$C$4:$C$1003,MATCH($B25,'Lead Management'!$A$4:$A$1003,0)),"") | H25: =IF($A25="","",Settings!$B$8) | P25: =IF($B25="","",IF(COUNTIF(Customers!$B$4:$B$1003,$B25)>0,"Yes","No")) | Q25: =IF($E25="","",IF($E25>TODAY(),"Scheduled",TODAY()-$E25))
C26: =IFERROR(INDEX('Lead Management'!$B$4:$B$1003,MATCH($B26,'Lead Management'!$A$4:$A$1003,0)),"") | D26: =IFERROR(INDEX('Lead Management'!$C$4:$C$1003,MATCH($B26,'Lead Management'!$A$4:$A$1003,0)),"") | H26: =IF($A26="","",Settings!$B$8) | P26: =IF($B26="","",IF(COUNTIF(Customers!$B$4:$B$1003,$B26)>0,"Yes","No")) | Q26: =IF($E26="","",IF($E26>TODAY(),"Scheduled",TODAY()-$E26))
C27: =IFERROR(INDEX('Lead Management'!$B$4:$B$1003,MATCH($B27,'Lead Management'!$A$4:$A$1003,0)),"") | D27: =IFERROR(INDEX('Lead Management'!$C$4:$C$1003,MATCH($B27,'Lead Management'!$A$4:$A$1003,0)),"") | H27: =IF($A27="","",Settings!$B$8) | P27: =IF($B27="","",IF(COUNTIF(Customers!$B$4:$B$1003,$B27)>0,"Yes","No")) | Q27: =IF($E27="","",IF($E27>TODAY(),"Scheduled",TODAY()-$E27))
C28: =IFERROR(INDEX('Lead Management'!$B$4:$B$1003,MATCH($B28,'Lead Management'!$A$4:$A$1003,0)),"") | D28: =IFERROR(INDEX('Lead Management'!$C$4:$C$1003,MATCH($B28,'Lead Management'!$A$4:$A$1003,0)),"") | H28: =IF($A28="","",Settings!$B$8) | P28: =IF($B28="","",IF(COUNTIF(Customers!$B$4:$B$1003,$B28)>0,"Yes","No")) | Q28: =IF($E28="","",IF($E28>TODAY(),"Scheduled",TODAY()-$E28))
C29: =IFERROR(INDEX('Lead Management'!$B$4:$B$1003,MATCH($B29,'Lead Management'!$A$4:$A$1003,0)),"") | D29: =IFERROR(INDEX('Lead Management'!$C$4:$C$1003,MATCH($B29,'Lead Management'!$A$4:$A$1003,0)),"") | H29: =IF($A29="","",Settings!$B$8) | P29: =IF($B29="","",IF(COUNTIF(Customers!$B$4:$B$1003,$B29)>0,"Yes","No")) | Q29: =IF($E29="","",IF($E29>TODAY(),"Scheduled",TODAY()-$E29))
C30: =IFERROR(INDEX('Lead Management'!$B$4:$B$1003,MATCH($B30,'Lead Management'!$A$4:$A$1003,0)),"") | D30: =IFERROR(INDEX('Lead Management'!$C$4:$C$1003,MATCH($B30,'Lead Management'!$A$4:$A$1003,0)),"") | H30: =IF($A30="","",Settings!$B$8) | P30: =IF($B30="","",IF(COUNTIF(Customers!$B$4:$B$1003,$B30)>0,"Yes","No")) | Q30: =IF($E30="","",IF($E30>TODAY(),"Scheduled",TODAY()-$E30))
C31: =IFERROR(INDEX('Lead Management'!$B$4:$B$1003,MATCH($B31,'Lead Management'!$A$4:$A$1003,0)),"") | D31: =IFERROR(INDEX('Lead Management'!$C$4:$C$1003,MATCH($B31,'Lead Management'!$A$4:$A$1003,0)),"") | H31: =IF($A31="","",Settings!$B$8) | P31: =IF($B31="","",IF(COUNTIF(Customers!$B$4:$B$1003,$B31)>0,"Yes","No")) | Q31: =IF($E31="","",IF($E31>TODAY(),"Scheduled",TODAY()-$E31))
C32: =IFERROR(INDEX('Lead Management'!$B$4:$B$1003,MATCH($B32,'Lead Management'!$A$4:$A$1003,0)),"") | D32: =IFERROR(INDEX('Lead Management'!$C$4:$C$1003,MATCH($B32,'Lead Management'!$A$4:$A$1003,0)),"") | H32: =IF($A32="","",Settings!$B$8) | P32: =IF($B32="","",IF(COUNTIF(Customers!$B$4:$B$1003,$B32)>0,"Yes","No")) | Q32: =IF($E32="","",IF($E32>TODAY(),"Scheduled",TODAY()-$E32))
C33: =IFERROR(INDEX('Lead Management'!$B$4:$B$1003,MATCH($B33,'Lead Management'!$A$4:$A$1003,0)),"") | D33: =IFERROR(INDEX('Lead Management'!$C$4:$C$1003,MATCH($B33,'Lead Management'!$A$4:$A$1003,0)),"") | H33: =IF($A33="","",Settings!$B$8) | P33: =IF($B33="","",IF(COUNTIF(Customers!$B$4:$B$1003,$B33)>0,"Yes","No")) | Q33: =IF($E33="","",IF($E33>TODAY(),"Scheduled",TODAY()-$E33))
... C203: =IFERROR(INDEX('Lead Management'!$B$4:$B$1003,MATCH($B203,'Lead Management'!$A$4:$A$1003,0)),"") | D203: =IFERROR(INDEX('Lead Management'!$C$4:$C$1003,MATCH($B203,'Lead Management'!$A$4:$A$1003,0)),"") | H203: =IF($A203="","",Settings!$B$8) | P203: =IF($B203="","",IF(COUNTIF(Customers!$B$4:$B$1003,$B203)>0,"Yes","No")) | Q203: =IF($E203="","",IF($E203>TODAY(),"Scheduled",TODAY()-$E203))

Sheet Customers
A1: VUSLAT RECRUITMENT COMPANY | CUSTOMERS
A2: Type the Customer ID, Lead ID, destination country and manager. Everything else - name, price, paid, balance, current stage and document progress - is calculated from the other sheets.
A3: Customer ID | B3: Lead ID | C3: Full Name | D3: Phone | E3: Passport Number | F3: Destination Country | G3: Job Position | H3: Employer | I3: Contract No | J3: Contract Date | K3: Assigned Manager | L3: Package Price (TJS) | M3: Total Paid (TJS) | N3: Balance (TJS) | O3: Payment Progress | P3: Current Stage | Q3: Documents % | R3: Customer Status | S3: Lead Source | T3: Registration Date | U3: Notes
A4: CUS-001 | B4: LD-001 | C4: =IFERROR(INDEX('Lead Management'!$B$4:$B$1003,MATCH($B4,'Lead Management'!$A$4:$A$1003,0)),"") -> Firdavs Rahmonov | D4: =IFERROR(INDEX('Lead Management'!$C$4:$C$1003,MATCH($B4,'Lead Management'!$A$4:$A$1003,0)),"") -> +992 91 203 1137 | E4: =IFERROR(INDEX('Lead Management'!$F$4:$F$1003,MATCH($B4,'Lead Management'!$A$4:$A$1003,0)),"") -> A4101373 | F4: Poland | G4: Welder | H4: Stal-Bud Sp. z o.o. | I4: CTR-2026-001 | J4: 46039 | K4: Nilufar Karimova | L4: =IF($F4="","",IFERROR(INDEX(Settings!$B$18:$B$27,MATCH($F4,Settings!$A$18:$A$27,0)),"")) -> 22000 | M4: =IF($A4="","",SUMIFS(Finance!$E$4:$E$1003,Finance!$B$4:$B$1003,$A4,Finance!$J$4:$J$1003,"Paid")) -> 22000 | N4: =IF($A4="","",IFERROR($L4-$M4,"")) -> 0 | O4: =IF($A4="","",IFERROR($M4/$L4,"")) -> 1 | P4: =IFERROR(INDEX('Process Tracking'!$E$5:$E$1003,MATCH($A4,'Process Tracking'!$A$5:$A$1003,0)),"") -> Case Completed | Q4: =IFERROR(INDEX(Documents!$Q$4:$Q$1003,MATCH($A4,Documents!$A$4:$A$1003,0)),"") -> 1 | R4: Completed | S4: =IFERROR(INDEX('Lead Management'!$O$4:$O$1003,MATCH($B4,'Lead Management'!$A$4:$A$1003,0)),"") -> Instagram | T4: =IFERROR(INDEX('Lead Management'!$P$4:$P$1003,MATCH($B4,'Lead Management'!$A$4:$A$1003,0)),"") -> 46030
A5: CUS-002 | B5: LD-002 | C5: =IFERROR(INDEX('Lead Management'!$B$4:$B$1003,MATCH($B5,'Lead Management'!$A$4:$A$1003,0)),"") -> Nilufar Sharipova | D5: =IFERROR(INDEX('Lead Management'!$C$4:$C$1003,MATCH($B5,'Lead Management'!$A$4:$A$1003,0)),"") -> +992 92 206 1274 | E5: =IFERROR(INDEX('Lead Management'!$F$4:$F$1003,MATCH($B5,'Lead Management'!$A$4:$A$1003,0)),"") -> A4102746 | F5: Germany | G5: Warehouse Operator | H5: Nordbau GmbH | I5: CTR-2026-002 | J5: 46046 | K5: Jamshed Sattorov | L5: =IF($F5="","",IFERROR(INDEX(Settings!$B$18:$B$27,MATCH($F5,Settings!$A$18:$A$27,0)),"")) -> 32000 | M5: =IF($A5="","",SUMIFS(Finance!$E$4:$E$1003,Finance!$B$4:$B$1003,$A5,Finance!$J$4:$J$1003,"Paid")) -> 32000 | N5: =IF($A5="","",IFERROR($L5-$M5,"")) -> 0 | O5: =IF($A5="","",IFERROR($M5/$L5,"")) -> 1 | P5: =IFERROR(INDEX('Process Tracking'!$E$5:$E$1003,MATCH($A5,'Process Tracking'!$A$5:$A$1003,0)),"") -> Case Completed | Q5: =IFERROR(INDEX(Documents!$Q$4:$Q$1003,MATCH($A5,Documents!$A$4:$A$1003,0)),"") -> 1 | R5: Completed | S5: =IFERROR(INDEX('Lead Management'!$O$4:$O$1003,MATCH($B5,'Lead Management'!$A$4:$A$1003,0)),"") -> Instagram | T5: =IFERROR(INDEX('Lead Management'!$P$4:$P$1003,MATCH($B5,'Lead Management'!$A$4:$A$1003,0)),"") -> 46037
A6: CUS-003 | B6: LD-003 | C6: =IFERROR(INDEX('Lead Management'!$B$4:$B$1003,MATCH($B6,'Lead Management'!$A$4:$A$1003,0)),"") -> Jamshed Karimov | D6: =IFERROR(INDEX('Lead Management'!$C$4:$C$1003,MATCH($B6,'Lead Management'!$A$4:$A$1003,0)),"") -> +992 93 209 1411 | E6: =IFERROR(INDEX('Lead Management'!$F$4:$F$1003,MATCH($B6,'Lead Management'!$A$4:$A$1003,0)),"") -> A4104119 | F6: Czech Republic | G6: Construction Worker | H6: Moravia Logistic a.s. | I6: CTR-2026-003 | J6: 46067 | K6: Dilnoza Aliyeva | L6: =IF($F6="","",IFERROR(INDEX(Settings!$B$18:$B$27,MATCH($F6,Settings!$A$18:$A$27,0)),"")) -> 25000 | M6: =IF($A6="","",SUMIFS(Finance!$E$4:$E$1003,Finance!$B$4:$B$1003,$A6,Finance!$J$4:$J$1003,"Paid")) -> 25000 | N6: =IF($A6="","",IFERROR($L6-$M6,"")) -> 0 | O6: =IF($A6="","",IFERROR($M6/$L6,"")) -> 1 | P6: =IFERROR(INDEX('Process Tracking'!$E$5:$E$1003,MATCH($A6,'Process Tracking'!$A$5:$A$1003,0)),"") -> Customer Departed to Europe | Q6: =IFERROR(INDEX(Documents!$Q$4:$Q$1003,MATCH($A6,Documents!$A$4:$A$1003,0)),"") -> 1 | R6: Active | S6: =IFERROR(INDEX('Lead Management'!$O$4:$O$1003,MATCH($B6,'Lead Management'!$A$4:$A$1003,0)),"") -> Facebook | T6: =IFERROR(INDEX('Lead Management'!$P$4:$P$1003,MATCH($B6,'Lead Management'!$A$4:$A$1003,0)),"") -> 46058
A7: CUS-004 | B7: LD-004 | C7: =IFERROR(INDEX('Lead Management'!$B$4:$B$1003,MATCH($B7,'Lead Management'!$A$4:$A$1003,0)),"") -> Zarina Nazriyeva | D7: =IFERROR(INDEX('Lead Management'!$C$4:$C$1003,MATCH($B7,'Lead Management'!$A$4:$A$1003,0)),"") -> +992 94 212 1548 | E7: =IFERROR(INDEX('Lead Management'!$F$4:$F$1003,MATCH($B7,'Lead Management'!$A$4:$A$1003,0)),"") -> A4105492 | F7: Poland | G7: Electrician | H7: Stal-Bud Sp. z o.o. | I7: CTR-2026-004 | J7: 46074 | K7: Nilufar Karimova | L7: =IF($F7="","",IFERROR(INDEX(Settings!$B$18:$B$27,MATCH($F7,Settings!$A$18:$A$27,0)),"")) -> 22000 | M7: =IF($A7="","",SUMIFS(Finance!$E$4:$E$1003,Finance!$B$4:$B$1003,$A7,Finance!$J$4:$J$1003,"Paid")) -> 22000 | N7: =IF($A7="","",IFERROR($L7-$M7,"")) -> 0 | O7: =IF($A7="","",IFERROR($M7/$L7,"")) -> 1 | P7: =IFERROR(INDEX('Process Tracking'!$E$5:$E$1003,MATCH($A7,'Process Tracking'!$A$5:$A$1003,0)),"") -> Flight Ticket Prepared | Q7: =IFERROR(INDEX(Documents!$Q$4:$Q$1003,MATCH($A7,Documents!$A$4:$A$1003,0)),"") -> 1 | R7: Active | S7: =IFERROR(INDEX('Lead Management'!$O$4:$O$1003,MATCH($B7,'Lead Management'!$A$4:$A$1003,0)),"") -> Instagram | T7: =IFERROR(INDEX('Lead Management'!$P$4:$P$1003,MATCH($B7,'Lead Management'!$A$4:$A$1003,0)),"") -> 46065
A8: CUS-005 | B8: LD-005 | C8: =IFERROR(INDEX('Lead Management'!$B$4:$B$1003,MATCH($B8,'Lead Management'!$A$4:$A$1003,0)),"") -> Bakhtiyor Umarov | D8: =IFERROR(INDEX('Lead Management'!$C$4:$C$1003,MATCH($B8,'Lead Management'!$A$4:$A$1003,0)),"") -> +992 95 215 1685 | E8: =IFERROR(INDEX('Lead Management'!$F$4:$F$1003,MATCH($B8,'Lead Management'!$A$4:$A$1003,0)),"") -> A4106865 | F8: Slovakia | G8: Truck Driver (CE) | H8: Tatra Works s.r.o. | I8: CTR-2026-005 | J8: 46053 | K8: Jamshed Sattorov | L8: =IF($F8="","",IFERROR(INDEX(Settings!$B$18:$B$27,MATCH($F8,Settings!$A$18:$A$27,0)),"")) -> 24000 | M8: =IF($A8="","",SUMIFS(Finance!$E$4:$E$1003,Finance!$B$4:$B$1003,$A8,Finance!$J$4:$J$1003,"Paid")) -> 18000 | N8: =IF($A8="","",IFERROR($L8-$M8,"")) -> 6000 | O8: =IF($A8="","",IFERROR($M8/$L8,"")) -> 0.75 | P8: =IFERROR(INDEX('Process Tracking'!$E$5:$E$1003,MATCH($A8,'Process Tracking'!$A$5:$A$1003,0)),"") -> Visa Approved | Q8: =IFERROR(INDEX(Documents!$Q$4:$Q$1003,MATCH($A8,Documents!$A$4:$A$1003,0)),"") -> 0.90909091 | R8: Active | S8: =IFERROR(INDEX('Lead Management'!$O$4:$O$1003,MATCH($B8,'Lead Management'!$A$4:$A$1003,0)),"") -> Website | T8: =IFERROR(INDEX('Lead Management'!$P$4:$P$1003,MATCH($B8,'Lead Management'!$A$4:$A$1003,0)),"") -> 46044
A9: CUS-006 | B9: LD-006 | C9: =IFERROR(INDEX('Lead Management'!$B$4:$B$1003,MATCH($B9,'Lead Management'!$A$4:$A$1003,0)),"") -> Manizha Qodirova | D9: =IFERROR(INDEX('Lead Management'!$C$4:$C$1003,MATCH($B9,'Lead Management'!$A$4:$A$1003,0)),"") -> +992 96 218 1822 | E9: =IFERROR(INDEX('Lead Management'!$F$4:$F$1003,MATCH($B9,'Lead Management'!$A$4:$A$1003,0)),"") -> A4108238 | F9: Germany | G9: Chef | H9: Nordbau GmbH | I9: CTR-2026-006 | J9: 46080 | K9: Dilnoza Aliyeva | L9: =IF($F9="","",IFERROR(INDEX(Settings!$B$18:$B$27,MATCH($F9,Settings!$A$18:$A$27,0)),"")) -> 32000 | M9: =IF($A9="","",SUMIFS(Finance!$E$4:$E$1003,Finance!$B$4:$B$1003,$A9,Finance!$J$4:$J$1003,"Paid")) -> 24000 | N9: =IF($A9="","",IFERROR($L9-$M9,"")) -> 8000 | O9: =IF($A9="","",IFERROR($M9/$L9,"")) -> 0.75 | P9: =IFERROR(INDEX('Process Tracking'!$E$5:$E$1003,MATCH($A9,'Process Tracking'!$A$5:$A$1003,0)),"") -> Visa Rejected | Q9: =IFERROR(INDEX(Documents!$Q$4:$Q$1003,MATCH($A9,Documents!$A$4:$A$1003,0)),"") -> 0.81818182 | R9: Cancelled | S9: =IFERROR(INDEX('Lead Management'!$O$4:$O$1003,MATCH($B9,'Lead Management'!$A$4:$A$1003,0)),"") -> Referral | T9: =IFERROR(INDEX('Lead Management'!$P$4:$P$1003,MATCH($B9,'Lead Management'!$A$4:$A$1003,0)),"") -> 46071 | U9: Visa refused by the German embassy - appeal not requested, case closed.
A10: CUS-007 | B10: LD-007 | C10: =IFERROR(INDEX('Lead Management'!$B$4:$B$1003,MATCH($B10,'Lead Management'!$A$4:$A$1003,0)),"") -> Rustam Sattorov | D10: =IFERROR(INDEX('Lead Management'!$C$4:$C$1003,MATCH($B10,'Lead Management'!$A$4:$A$1003,0)),"") -> +992 97 221 1959 | E10: =IFERROR(INDEX('Lead Management'!$F$4:$F$1003,MATCH($B10,'Lead Management'!$A$4:$A$1003,0)),"") -> A4109611 | F10: Poland | G10: Construction Worker | H10: Stal-Bud Sp. z o.o. | I10: CTR-2026-007 | J10: 46094 | K10: Nilufar Karimova | L10: =IF($F10="","",IFERROR(INDEX(Settings!$B$18:$B$27,MATCH($F10,Settings!$A$18:$A$27,0)),"")) -> 22000 | M10: =IF($A10="","",SUMIFS(Finance!$E$4:$E$1003,Finance!$B$4:$B$1003,$A10,Finance!$J$4:$J$1003,"Paid")) -> 16500 | N10: =IF($A10="","",IFERROR($L10-$M10,"")) -> 5500 | O10: =IF($A10="","",IFERROR($M10/$L10,"")) -> 0.75 | P10: =IFERROR(INDEX('Process Tracking'!$E$5:$E$1003,MATCH($A10,'Process Tracking'!$A$5:$A$1003,0)),"") -> Visa Decision Pending | Q10: =IFERROR(INDEX(Documents!$Q$4:$Q$1003,MATCH($A10,Documents!$A$4:$A$1003,0)),"") -> 0.81818182 | R10: Active | S10: =IFERROR(INDEX('Lead Management'!$O$4:$O$1003,MATCH($B10,'Lead Management'!$A$4:$A$1003,0)),"") -> Instagram | T10: =IFERROR(INDEX('Lead Management'!$P$4:$P$1003,MATCH($B10,'Lead Management'!$A$4:$A$1003,0)),"") -> 46085
A11: CUS-008 | B11: LD-008 | C11: =IFERROR(INDEX('Lead Management'!$B$4:$B$1003,MATCH($B11,'Lead Management'!$A$4:$A$1003,0)),"") -> Dilnoza Aliyeva | D11: =IFERROR(INDEX('Lead Management'!$C$4:$C$1003,MATCH($B11,'Lead Management'!$A$4:$A$1003,0)),"") -> +992 90 224 2096 | E11: =IFERROR(INDEX('Lead Management'!$F$4:$F$1003,MATCH($B11,'Lead Management'!$A$4:$A$1003,0)),"") -> A4110984 | F11: Lithuania | G11: Warehouse Operator | H11: Baltic Logistics UAB | I11: CTR-2026-008 | J11: 46101 | K11: Jamshed Sattorov | L11: =IF($F11="","",IFERROR(INDEX(Settings!$B$18:$B$27,MATCH($F11,Settings!$A$18:$A$27,0)),"")) -> 21000 | M11: =IF($A11="","",SUMIFS(Finance!$E$4:$E$1003,Finance!$B$4:$B$1003,$A11,Finance!$J$4:$J$1003,"Paid")) -> 15750 | N11: =IF($A11="","",IFERROR($L11-$M11,"")) -> 5250 | O11: =IF($A11="","",IFERROR($M11/$L11,"")) -> 0.75 | P11: =IFERROR(INDEX('Process Tracking'!$E$5:$E$1003,MATCH($A11,'Process Tracking'!$A$5:$A$1003,0)),"") -> Visa Application Submitted | Q11: =IFERROR(INDEX(Documents!$Q$4:$Q$1003,MATCH($A11,Documents!$A$4:$A$1003,0)),"") -> 0.81818182 | R11: Active | S11: =IFERROR(INDEX('Lead Management'!$O$4:$O$1003,MATCH($B11,'Lead Management'!$A$4:$A$1003,0)),"") -> Instagram | T11: =IFERROR(INDEX('Lead Management'!$P$4:$P$1003,MATCH($B11,'Lead Management'!$A$4:$A$1003,0)),"") -> 46092
A12: CUS-009 | B12: LD-009 | C12: =IFERROR(INDEX('Lead Management'!$B$4:$B$1003,MATCH($B12,'Lead Management'!$A$4:$A$1003,0)),"") -> Sherali Yusupov | D12: =IFERROR(INDEX('Lead Management'!$C$4:$C$1003,MATCH($B12,'Lead Management'!$A$4:$A$1003,0)),"") -> +992 91 227 2233 | E12: =IFERROR(INDEX('Lead Management'!$F$4:$F$1003,MATCH($B12,'Lead Management'!$A$4:$A$1003,0)),"") -> A4112357 | F12: Czech Republic | G12: Plumber | H12: Moravia Logistic a.s. | I12: CTR-2026-009 | J12: 46108 | K12: Dilnoza Aliyeva | L12: =IF($F12="","",IFERROR(INDEX(Settings!$B$18:$B$27,MATCH($F12,Settings!$A$18:$A$27,0)),"")) -> 25000 | M12: =IF($A12="","",SUMIFS(Finance!$E$4:$E$1003,Finance!$B$4:$B$1003,$A12,Finance!$J$4:$J$1003,"Paid")) -> 12500 | N12: =IF($A12="","",IFERROR($L12-$M12,"")) -> 12500 | O12: =IF($A12="","",IFERROR($M12/$L12,"")) -> 0.5 | P12: =IFERROR(INDEX('Process Tracking'!$E$5:$E$1003,MATCH($A12,'Process Tracking'!$A$5:$A$1003,0)),"") -> Embassy Appointment Booked | Q12: =IFERROR(INDEX(Documents!$Q$4:$Q$1003,MATCH($A12,Documents!$A$4:$A$1003,0)),"") -> 0.81818182 | R12: Active | S12: =IFERROR(INDEX('Lead Management'!$O$4:$O$1003,MATCH($B12,'Lead Management'!$A$4:$A$1003,0)),"") -> Facebook | T12: =IFERROR(INDEX('Lead Management'!$P$4:$P$1003,MATCH($B12,'Lead Management'!$A$4:$A$1003,0)),"") -> 46099 | U12: Payment 3 is overdue, accountant notified.
A13: CUS-010 | B13: LD-010 | C13: =IFERROR(INDEX('Lead Management'!$B$4:$B$1003,MATCH($B13,'Lead Management'!$A$4:$A$1003,0)),"") -> Malika Ismoilova | D13: =IFERROR(INDEX('Lead Management'!$C$4:$C$1003,MATCH($B13,'Lead Management'!$A$4:$A$1003,0)),"") -> +992 92 230 2370 | E13: =IFERROR(INDEX('Lead Management'!$F$4:$F$1003,MATCH($B13,'Lead Management'!$A$4:$A$1003,0)),"") -> A4113730 | F13: Poland | G13: Painter | H13: Stal-Bud Sp. z o.o. | I13: CTR-2026-010 | J13: 46123 | K13: Nilufar Karimova | L13: =IF($F13="","",IFERROR(INDEX(Settings!$B$18:$B$27,MATCH($F13,Settings!$A$18:$A$27,0)),"")) -> 22000 | M13: =IF($A13="","",SUMIFS(Finance!$E$4:$E$1003,Finance!$B$4:$B$1003,$A13,Finance!$J$4:$J$1003,"Paid")) -> 16500 | N13: =IF($A13="","",IFERROR($L13-$M13,"")) -> 5500 | O13: =IF($A13="","",IFERROR($M13/$L13,"")) -> 0.75 | P13: =IFERROR(INDEX('Process Tracking'!$E$5:$E$1003,MATCH($A13,'Process Tracking'!$A$5:$A$1003,0)),"") -> Employment Contract Issued | Q13: =IFERROR(INDEX(Documents!$Q$4:$Q$1003,MATCH($A13,Documents!$A$4:$A$1003,0)),"") -> 0.81818182 | R13: Active | S13: =IFERROR(INDEX('Lead Management'!$O$4:$O$1003,MATCH($B13,'Lead Management'!$A$4:$A$1003,0)),"") -> Instagram | T13: =IFERROR(INDEX('Lead Management'!$P$4:$P$1003,MATCH($B13,'Lead Management'!$A$4:$A$1003,0)),"") -> 46114
A14: CUS-011 | B14: LD-011 | C14: =IFERROR(INDEX('Lead Management'!$B$4:$B$1003,MATCH($B14,'Lead Management'!$A$4:$A$1003,0)),"") -> Farrukh Davlatov | D14: =IFERROR(INDEX('Lead Management'!$C$4:$C$1003,MATCH($B14,'Lead Management'!$A$4:$A$1003,0)),"") -> +992 93 233 2507 | E14: =IFERROR(INDEX('Lead Management'!$F$4:$F$1003,MATCH($B14,'Lead Management'!$A$4:$A$1003,0)),"") -> A4115103 | F14: Hungary | G14: Agricultural Worker | H14: Duna Ipari Kft. | I14: CTR-2026-011 | J14: 46115 | K14: Jamshed Sattorov | L14: =IF($F14="","",IFERROR(INDEX(Settings!$B$18:$B$27,MATCH($F14,Settings!$A$18:$A$27,0)),"")) -> 23000 | M14: =IF($A14="","",SUMIFS(Finance!$E$4:$E$1003,Finance!$B$4:$B$1003,$A14,Finance!$J$4:$J$1003,"Paid")) -> 11500 | N14: =IF($A14="","",IFERROR($L14-$M14,"")) -> 11500 | O14: =IF($A14="","",IFERROR($M14/$L14,"")) -> 0.5 | P14: =IFERROR(INDEX('Process Tracking'!$E$5:$E$1003,MATCH($A14,'Process Tracking'!$A$5:$A$1003,0)),"") -> Documents Sent to Employer | Q14: =IFERROR(INDEX(Documents!$Q$4:$Q$1003,MATCH($A14,Documents!$A$4:$A$1003,0)),"") -> 0.63636364 | R14: Active | S14: =IFERROR(INDEX('Lead Management'!$O$4:$O$1003,MATCH($B14,'Lead Management'!$A$4:$A$1003,0)),"") -> Website | T14: =IFERROR(INDEX('Lead Management'!$P$4:$P$1003,MATCH($B14,'Lead Management'!$A$4:$A$1003,0)),"") -> 46106 | U14: Waiting for the apostilled diploma from the client.
A15: CUS-012 | B15: LD-012 | C15: =IFERROR(INDEX('Lead Management'!$B$4:$B$1003,MATCH($B15,'Lead Management'!$A$4:$A$1003,0)),"") -> Gulnora Safarova | D15: =IFERROR(INDEX('Lead Management'!$C$4:$C$1003,MATCH($B15,'Lead Management'!$A$4:$A$1003,0)),"") -> +992 94 236 2644 | E15: =IFERROR(INDEX('Lead Management'!$F$4:$F$1003,MATCH($B15,'Lead Management'!$A$4:$A$1003,0)),"") -> A4116476 | F15: Romania | G15: Cleaner | H15: Carpat Agro SRL | I15: CTR-2026-012 | J15: 46130 | K15: Dilnoza Aliyeva | L15: =IF($F15="","",IFERROR(INDEX(Settings!$B$18:$B$27,MATCH($F15,Settings!$A$18:$A$27,0)),"")) -> 19000 | M15: =IF($A15="","",SUMIFS(Finance!$E$4:$E$1003,Finance!$B$4:$B$1003,$A15,Finance!$J$4:$J$1003,"Paid")) -> 9500 | N15: =IF($A15="","",IFERROR($L15-$M15,"")) -> 9500 | O15: =IF($A15="","",IFERROR($M15/$L15,"")) -> 0.5 | P15: =IFERROR(INDEX('Process Tracking'!$E$5:$E$1003,MATCH($A15,'Process Tracking'!$A$5:$A$1003,0)),"") -> Documents Being Prepared | Q15: =IFERROR(INDEX(Documents!$Q$4:$Q$1003,MATCH($A15,Documents!$A$4:$A$1003,0)),"") -> 0.36363636 | R15: Active | S15: =IFERROR(INDEX('Lead Management'!$O$4:$O$1003,MATCH($B15,'Lead Management'!$A$4:$A$1003,0)),"") -> Referral | T15: =IFERROR(INDEX('Lead Management'!$P$4:$P$1003,MATCH($B15,'Lead Management'!$A$4:$A$1003,0)),"") -> 46121
C16: =IFERROR(INDEX('Lead Management'!$B$4:$B$1003,MATCH($B16,'Lead Management'!$A$4:$A$1003,0)),"") | D16: =IFERROR(INDEX('Lead Management'!$C$4:$C$1003,MATCH($B16,'Lead Management'!$A$4:$A$1003,0)),"") | E16: =IFERROR(INDEX('Lead Management'!$F$4:$F$1003,MATCH($B16,'Lead Management'!$A$4:$A$1003,0)),"") | L16: =IF($F16="","",IFERROR(INDEX(Settings!$B$18:$B$27,MATCH($F16,Settings!$A$18:$A$27,0)),"")) | M16: =IF($A16="","",SUMIFS(Finance!$E$4:$E$1003,Finance!$B$4:$B$1003,$A16,Finance!$J$4:$J$1003,"Paid")) | N16: =IF($A16="","",IFERROR($L16-$M16,"")) | O16: =IF($A16="","",IFERROR($M16/$L16,"")) | P16: =IFERROR(INDEX('Process Tracking'!$E$5:$E$1003,MATCH($A16,'Process Tracking'!$A$5:$A$1003,0)),"") | Q16: =IFERROR(INDEX(Documents!$Q$4:$Q$1003,MATCH($A16,Documents!$A$4:$A$1003,0)),"") | S16: =IFERROR(INDEX('Lead Management'!$O$4:$O$1003,MATCH($B16,'Lead Management'!$A$4:$A$1003,0)),"") | T16: =IFERROR(INDEX('Lead Management'!$P$4:$P$1003,MATCH($B16,'Lead Management'!$A$4:$A$1003,0)),"")
C17: =IFERROR(INDEX('Lead Management'!$B$4:$B$1003,MATCH($B17,'Lead Management'!$A$4:$A$1003,0)),"") | D17: =IFERROR(INDEX('Lead Management'!$C$4:$C$1003,MATCH($B17,'Lead Management'!$A$4:$A$1003,0)),"") | E17: =IFERROR(INDEX('Lead Management'!$F$4:$F$1003,MATCH($B17,'Lead Management'!$A$4:$A$1003,0)),"") | L17: =IF($F17="","",IFERROR(INDEX(Settings!$B$18:$B$27,MATCH($F17,Settings!$A$18:$A$27,0)),"")) | M17: =IF($A17="","",SUMIFS(Finance!$E$4:$E$1003,Finance!$B$4:$B$1003,$A17,Finance!$J$4:$J$1003,"Paid")) | N17: =IF($A17="","",IFERROR($L17-$M17,"")) | O17: =IF($A17="","",IFERROR($M17/$L17,"")) | P17: =IFERROR(INDEX('Process Tracking'!$E$5:$E$1003,MATCH($A17,'Process Tracking'!$A$5:$A$1003,0)),"") | Q17: =IFERROR(INDEX(Documents!$Q$4:$Q$1003,MATCH($A17,Documents!$A$4:$A$1003,0)),"") | S17: =IFERROR(INDEX('Lead Management'!$O$4:$O$1003,MATCH($B17,'Lead Management'!$A$4:$A$1003,0)),"") | T17: =IFERROR(INDEX('Lead Management'!$P$4:$P$1003,MATCH($B17,'Lead Management'!$A$4:$A$1003,0)),"")
C18: =IFERROR(INDEX('Lead Management'!$B$4:$B$1003,MATCH($B18,'Lead Management'!$A$4:$A$1003,0)),"") | D18: =IFERROR(INDEX('Lead Management'!$C$4:$C$1003,MATCH($B18,'Lead Management'!$A$4:$A$1003,0)),"") | E18: =IFERROR(INDEX('Lead Management'!$F$4:$F$1003,MATCH($B18,'Lead Management'!$A$4:$A$1003,0)),"") | L18: =IF($F18="","",IFERROR(INDEX(Settings!$B$18:$B$27,MATCH($F18,Settings!$A$18:$A$27,0)),"")) | M18: =IF($A18="","",SUMIFS(Finance!$E$4:$E$1003,Finance!$B$4:$B$1003,$A18,Finance!$J$4:$J$1003,"Paid")) | N18: =IF($A18="","",IFERROR($L18-$M18,"")) | O18: =IF($A18="","",IFERROR($M18/$L18,"")) | P18: =IFERROR(INDEX('Process Tracking'!$E$5:$E$1003,MATCH($A18,'Process Tracking'!$A$5:$A$1003,0)),"") | Q18: =IFERROR(INDEX(Documents!$Q$4:$Q$1003,MATCH($A18,Documents!$A$4:$A$1003,0)),"") | S18: =IFERROR(INDEX('Lead Management'!$O$4:$O$1003,MATCH($B18,'Lead Management'!$A$4:$A$1003,0)),"") | T18: =IFERROR(INDEX('Lead Management'!$P$4:$P$1003,MATCH($B18,'Lead Management'!$A$4:$A$1003,0)),"")
